<?xml version="1.0"?>
<robot xmlns:sensor="http://playerstage.sourceforge.net/gazebo/xmlschema/#sensor"
       xmlns:controller="http://playerstage.sourceforge.net/gazebo/xmlschema/#controller"
       xmlns:interface="http://playerstage.sourceforge.net/gazebo/xmlschema/#interface"
       xmlns:xacro="http://ros.org/wiki/xacro">

	<!--include filename="$(find cob_description)/urdf/lbr/lbr.gazebo.xacro" /-->
	<!--include filename="$(find cob_description)/urdf/lbr/lbr.transmission.xacro" /-->

	<xacro:macro name="cob_kr16" params="parent name *origin">

		<!-- joint between base_link and arm_0_link -->
		<joint name="${name}_0_joint" type="fixed" >
			<insert_block name="origin" />
			<parent link="${parent}" />
			<child link="${name}_0_link" />
		</joint>

		<link name="${name}_0_link">
			<inertial>
				<origin xyz="0 0 0" rpy="0 0 0"/>
				<mass value="1.0"/>
				<inertia ixx="0.01" ixy="0" ixz="0" iyy="0.01" iyz="0" izz="0.01" />
			</inertial>

			<visual>
				<origin xyz="0 0 0" rpy="0 0 0" />
				<geometry>
					<!--cylinder radius="0.060" length="0.30"/-->
					<mesh filename="package://cob_kuka_description/meshes/kr16/joint_0.stl" />
				</geometry>
				<material name="Black" />
			</visual>

			<collision>
				<origin xyz="0 0 0" rpy="0 0 0" />
				<geometry>
					<box size="0.01 0.01 0.01"/>
				</geometry>
			</collision>
		</link>

		<!-- joint between arm_0_link and arm_1_link -->
		<joint name="${name}_1_joint" type="revolute">
		<origin xyz="0 0 0.390" rpy="${M_PI} 0 0"/>
			<parent link="${name}_0_link"/>
			<child link="${name}_1_link"/>
			<axis xyz="0 0 1"/>
			<calibration rising="${arm_1_ref}"/>
			<dynamics damping="10" />
			<limit effort="200" velocity="1.9634" lower="-2.9670" upper="2.9670"/>
			<safety_controller k_position="20" k_velocity="50" soft_lower_limit="${-2.9670 + 0.01}" soft_upper_limit="${2.9670 - 0.01}" />
		</joint>

		<link name="${name}_1_link">
			<inertial>
				<origin xyz="0 0 0" rpy="0 0 0" />
				<!--mass value="5.9907"/-->
				<mass value="2.0"/>
				<inertia ixx="0.01" ixy="0" ixz="0" iyy="0.01" iyz="0" izz="0.01" />
			</inertial>
			
			<visual>
				<origin xyz="0 0 0" rpy="0 0 0" />
				<geometry>
					<mesh filename="package://cob_kuka_description/meshes/kr16/joint_1.stl" />
					<!--cylinder radius="0.060" length="0.30"/-->
				</geometry>
				<material name="Orange" />
			</visual>
			
			<collision>
				<origin xyz="0 0 0" rpy="0 0 0" />
				<geometry>
					<!--mesh filename="package://cob_kuka_description/meshes/kr16/joint_1_collision.stl" /-->
					<cylinder radius="0.060" length="0.30"/>
				</geometry>
			</collision>
		</link>

		<!-- joint between arm_1_link and arm_2_link -->	
		<joint name="${name}_2_joint" type="revolute">
			<origin xyz="0.260 0.07 -0.285" rpy="${M_PI/2} 0 0"/>
			<parent link="${name}_1_link"/>
			<child link="${name}_2_link"/>
			<axis xyz="0 0 1"/>
			<calibration rising="${arm_2_ref}"/>
			<dynamics damping="10" />
			<limit effort="200" velocity="1.9634" lower="-2.0943" upper="2.0943"/>
			<safety_controller k_position="20" k_velocity="50" soft_lower_limit="${-2.0943 + 0.01}" 	soft_upper_limit="${2.0943 - 0.01}" />
		</joint>

		<link name="${name}_2_link">
			<inertial>
				<origin xyz="0 0 0" rpy="0 0 0"/>
				<!--mass value="5.734939"/-->
				<mass value="2.0"/>
				<inertia ixx="0.03" ixy="0" ixz="0" iyy="0.03" iyz="0" izz="0.03" />
			</inertial>
			
			<visual>
				<origin xyz="0 0 0" rpy="0 0 0" />
				<geometry>
					<mesh filename="package://cob_kuka_description/meshes/kr16/joint_2.stl" />
					<cylinder radius="0.060" length="0.30"/>
				</geometry>
				<material name="Black" />
			</visual>
			
			<collision>
				<origin xyz="0 0 0" rpy="0 0 0" />
				<geometry>
					<!--mesh filename="package://cob_kuka_description/meshes/kr16/joint_2_collision.stl"/-->
					<cylinder radius="0.060" length="0.30"/>
				</geometry>
			</collision>
		</link>

		<!-- joint between arm_2_link and arm_3_link -->	
		<joint name="${name}_3_joint" type="revolute">
			<origin xyz="0.680 0 -0.04" rpy="0 0 0"/>
			<parent link="${name}_2_link"/>
			<child link="${name}_3_link"/>
			<axis xyz="0 0 1"/>
			<calibration rising="${arm_3_ref}"/>
			<dynamics damping="5" />
			<limit effort="100" velocity="1.9634" lower="-2.9670" upper="2.9670"/>
			<safety_controller k_position="20" k_velocity="25" soft_lower_limit="${-2.9670 + 0.01}" soft_upper_limit="${2.9670 - 0.01}" />
		</joint>

		<link name="${name}_3_link">
			<inertial>
				<origin xyz="0 0 0" rpy="0 0 0"/>
				<!--mass value="4.214668"/-->
				<mass value="2.0"/>
				<inertia ixx="0.03" ixy="0" ixz="0" iyy="0.03" iyz="0" izz="0.03" />
			</inertial>
			
			<visual>
				<origin xyz="0 0 0" rpy="0 0 0" />
				<geometry>
					<mesh filename="package://cob_kuka_description/meshes/kr16/joint_3.stl" />
					<!--cylinder radius="0.060" length="0.30"/-->
				</geometry>
				<material name="Orange" />
			</visual>
			
			<collision>
				<origin xyz="0 0 0" rpy="0 0 0" />
				<geometry>
					<!--mesh filename="package://cob_kuka_description/meshes/kr16/joint_3_collision.stl"/-->
					<cylinder radius="0.060" length="0.30"/>
				</geometry>
			</collision>
		</link>	

		<!-- joint between arm_3_link and arm_4_link -->
		<joint name="${name}_4_joint" type="revolute">
			<origin xyz="0.400 0.035 0.118" rpy="0 -${M_PI/2} 0" />
			<parent link="${name}_3_link"/>
			<child link="${name}_4_link"/>
			<axis xyz="0 0 1" />
			<calibration rising="${arm_4_ref}"/>
			<dynamics damping="5" />
			<limit effort="100" velocity="1.9634" lower="-2.0943" upper="2.0943"/>
			<!--limit effort="176" velocity="0.4189" upper="2.0943951" lower="-2.0943951"/-->
			<safety_controller k_position="20" k_velocity="25" soft_lower_limit="${-2.0943 + 0.01}" soft_upper_limit="${2.0943 - 0.01}" />
		</joint>

		<link name="${name}_4_link">
			<inertial>
				<origin xyz="0 0 0" rpy="0 0 0"/>
				<!--mass value="3.669819"/-->
				<mass value="2.0"/>
				<inertia ixx="0.03" ixy="0" ixz="0" iyy="0.03" iyz="0" izz="0.03" />
			</inertial>
			
			<visual>
				<origin xyz="0 0 0" rpy="0 0 0" />
				<geometry>
					<mesh filename="package://cob_kuka_description/meshes/kr16/joint_4.stl" />
					<!--cylinder radius="0.060" length="0.30"/-->
				</geometry>
				<material name="Black" />
			</visual>
			
			<collision>
				<origin xyz="0 0 0" rpy="0 0 0" />
				<geometry>
					<!--mesh filename="package://cob_kuka_description/meshes/kr16/joint_4_collision.stl"/-->
					<cylinder radius="0.060" length="0.30"/>
				</geometry>
			</collision>
		</link>

		<!-- joint between arm_4_link and arm_5_link -->
		<joint name="${name}_5_joint" type="revolute">
			<origin xyz="0.1 0 -0.270" rpy="0 ${M_PI/2} 0" />
			<parent link="${name}_4_link"/>
			<child link="${name}_5_link"/>
			<axis xyz="0 0 1" />
			<calibration rising="${arm_5_ref}"/>
			<dynamics damping="5" />
			<limit effort="100" velocity="1.9634" lower="-2.9670" upper="2.9670" />
			<safety_controller k_position="20" k_velocity="25" soft_lower_limit="${-2.9670 + 0.01}" soft_upper_limit="${2.9670 - 0.01}" />
		</joint>

		<link name="${name}_5_link">
			<inertial>
				<origin xyz="0 0 0" rpy="0 0 0"/>
				<mass value="2.313272"/>
				<inertia ixx="0.03" ixy="0" ixz="0" iyy="0.03" iyz="0" izz="0.03" />
			</inertial>
			
			<visual>
				<origin xyz="0 0 0" rpy="0 0 0" />
				<geometry>
					<mesh filename="package://cob_kuka_description/meshes/kr16/joint_5.stl" />
					<!--cylinder radius="0.060" length="0.30"/-->
				</geometry>
				<material name="Orange" />
			</visual>
			
			<collision>
				<origin xyz="0 0 0" rpy="0 0 0" />
				<geometry>
					<!--mesh filename="package://cob_kuka_description/meshes/kr16/joint_5_collision.stl"/-->
					<cylinder radius="0.060" length="0.30"/>
				</geometry>
			</collision>
		</link>

		<!-- joint between arm_5_link and arm_6_link -->
		<joint name="${name}_6_joint" type="revolute">
			<origin xyz="0.158 0 -0.1" rpy="0 -${M_PI/2} 0" />  <!--origin xyz="0.115 0 0" rpy="0 -${M_PI/2} 0" /-->
			<parent link="${name}_5_link"/>
			<child link="${name}_6_link"/>
			<axis xyz="0 0 1" />
			<calibration rising="${arm_6_ref}"/>
			<dynamics damping="5" />
			<limit effort="30" velocity="1.9634" lower="-2.0943951" upper="2.0943951" />
			<!--limit effort="20.1" velocity="0.4363" upper="2.0943951" lower="-2.0943951" /-->
			<safety_controller k_position="20" k_velocity="25" soft_lower_limit="${-2.0943951 + 0.01}" soft_upper_limit="${2.0943951 - 0.01}" />
		</joint>

		<link name="${name}_6_link">
			<inertial>
				<origin xyz="0 0 0" rpy="0 0 0"/>
				<mass value="2.057856"/>
				<inertia ixx="0.01" ixy="0" ixz="0" iyy="0.01" iyz="0" izz="0.01" />
			</inertial>
			
			<visual>
				<origin xyz="0 0 0" rpy="0 0 0" />
				<geometry>
					<mesh filename="package://cob_kuka_description/meshes/kr16/joint_6.stl" />
					<!--cylinder radius="0.060" length="0.30"/-->
				</geometry>
				<material name="Black" />
			</visual>
			
			<collision>
				<origin xyz="0 0 0" rpy="0 0 0" />
				<geometry>
					<!--mesh filename="package://cob_kuka_description/meshes/kr16/joint_6_collision.stl"/-->
					<cylinder radius="0.060" length="0.30"/>
				</geometry>
			</collision>
		</link>

		<!-- extensions -->
		<xacro:cob_kr16_gazebo name="${name}" />
		<xacro:cob_kr16_transmission name="${name}" />

	</xacro:macro>

</robot>
